<?xml version="1.0" ?>
<robot name="arm" xmlns:xacro="http://www.ros.org/wiki/xacro">

<xacro:include filename="$(find arm_description)/urdf/materials.xacro" />
<xacro:include filename="$(find arm_description)/urdf/arm.trans" />
<xacro:include filename="$(find arm_description)/urdf/arm.gazebo" />
<link name="base_link">
   <inertial>
    <origin xyz="-0.002716977299773592 1.9808719046125134e-13 -0.002500000000000375" rpy="0 0 0"/>
    <mass value="2"/>
    <inertia ixx="7.2e-05" iyy="7.6e-05" izz="0.000147" ixy="-0.0" iyz="0.0" ixz="-0.04"/>
  </inertial>
  <visual>
    <origin xyz="0 0 0" rpy="0 0 0"/>
    <geometry>
      <mesh filename="package://arm_description/meshes/base_link.stl" scale="0.001 0.001 0.001"/>
    </geometry>
    <material name="steel_satin"/>
  </visual>
  <collision>
    <origin xyz="0 0 0" rpy="0 0 0"/>
    <geometry>
      <mesh filename="package://arm_description/meshes/base_link.stl" scale="0.001 0.001 0.001"/>
    </geometry>
  </collision>
</link>

<link name="link1_1">
  <inertial>
    <origin xyz="-0.1170701569437167 0.05258495071306836 0.24677061589144064" rpy="0 0 0"/>
    <mass value="0.6560949347888712"/>
    <inertia ixx="0.020432" iyy="0.024363" izz="0.005288" ixy="0.000756" iyz="-0.001594" ixz="0.009271"/>
  </inertial>
  <visual>
    <origin xyz="0.0375 -0.034 -0.0425" rpy="0 0 0"/>
    <geometry>
      <mesh filename="package://arm_description/meshes/link1_1.stl" scale="0.001 0.001 0.001"/>
    </geometry>
    <material name="default"/>
  </visual>
  <collision>
    <origin xyz="0.0375 -0.034 -0.0425" rpy="0 0 0"/>
    <geometry>
      <mesh filename="package://arm_description/meshes/link1_1.stl" scale="0.001 0.001 0.001"/>
    </geometry>
  </collision>
</link>

<link name="link2_1">
  <inertial>
    <origin xyz="0.0912652794492105 -0.04755997480137449 0.15715086928559246" rpy="0 0 0"/>
    <mass value="0.4295491979731537"/>
    <inertia ixx="0.0092" iyy="0.01219" izz="0.003285" ixy="0.00233" iyz="0.000401" ixz="-0.005183"/>
  </inertial>
  <visual>
    <origin xyz="0.235094 -0.046 -0.459007" rpy="0 0 0"/>
    <geometry>
      <mesh filename="package://arm_description/meshes/link2_1.stl" scale="0.001 0.001 0.001"/>
    </geometry>
    <material name="default"/>
  </visual>
  <collision>
    <origin xyz="0.235094 -0.046 -0.459007" rpy="0 0 0"/>
    <geometry>
      <mesh filename="package://arm_description/meshes/link2_1.stl" scale="0.001 0.001 0.001"/>
    </geometry>
  </collision>
</link>

<link name="tip_1">
  <inertial>
    <origin xyz="0.012554620120246197 2.599084142351771e-13 0.021619020423368274" rpy="0 0 0"/>
    <mass value="0.03924999999999999"/>
    <inertia ixx="7e-06" iyy="9e-06" izz="3e-06" ixy="0.0" iyz="0.0" ixz="-3e-06"/>
  </inertial>
  <visual>
    <origin xyz="-0.016007 0.0075 -0.891382" rpy="0 0 0"/>
    <geometry>
      <mesh filename="package://arm_description/meshes/tip_1.stl" scale="0.001 0.001 0.001"/>
    </geometry>
    <material name="steel_satin"/>
  </visual>
  <collision>
    <origin xyz="-0.016007 0.0075 -0.891382" rpy="0 0 0"/>
    <geometry>
      <mesh filename="package://arm_description/meshes/tip_1.stl" scale="0.001 0.001 0.001"/>
    </geometry>
  </collision>
</link>

<link name="shoulder_1">
  <inertial>
    <origin xyz="-0.00379841512801708 -4.326319553927361e-16 0.05885490789415437" rpy="0 0 0"/>
    <mass value="0.2699874429831712"/>
    <inertia ixx="0.000593" iyy="0.000639" izz="0.0003" ixy="0.0" iyz="-0.0" ixz="-1.7e-05"/>
  </inertial>
  <visual>
    <origin xyz="0.0 -0.0 0.0" rpy="0 0 0"/>
    <geometry>
      <mesh filename="package://arm_description/meshes/shoulder_1.stl" scale="0.001 0.001 0.001"/>
    </geometry>
    <material name="default"/>
  </visual>
  <collision>
    <origin xyz="0.0 -0.0 0.0" rpy="0 0 0"/>
    <geometry>
      <mesh filename="package://arm_description/meshes/shoulder_1.stl" scale="0.001 0.001 0.001"/>
    </geometry>
  </collision>
</link>

<joint name="Rev1" type="continuous">
  <origin xyz="-0.0375 0.034 0.0425" rpy="0 0 0"/>
  <parent link="shoulder_1"/>
  <child link="link1_1"/>
  <axis xyz="-0.0 1.0 -0.0"/>
</joint>

<joint name="Rev2" type="continuous">
  <origin xyz="-0.197594 0.012 0.416507" rpy="0 0 0"/>
  <parent link="link1_1"/>
  <child link="link2_1"/>
  <axis xyz="0.0 -1.0 0.0"/>
</joint>

<joint name="Rev3" type="revolute">
  <origin xyz="0.251101 -0.0535 0.432375" rpy="0 0 0"/>
  <parent link="link2_1"/>
  <child link="tip_1"/>
  <axis xyz="-0.0 1.0 0.0"/>
  <limit upper="1.22173" lower="-1.22173" effort="100" velocity="100"/>
</joint>

<joint name="Rev4" type="continuous">
  <origin xyz="0.0 0.0 0.0" rpy="0 0 0"/>
  <parent link="base_link"/>
  <child link="shoulder_1"/>
  <axis xyz="-0.0 0.0 1.0"/>
</joint>

</robot>
